<?xml version="1.0" ?>
<robot xmlns:xacro="http://ros.org/wiki/xacro" name="kawasaki_fs20n">

    <material name="Purple1">
        <color rgba="0.2 0.0 0.3 1.0"/>
    </material>
    <material name="Purple2">
        <color rgba="0.3 0.0 0.4 1.0"/>
    </material>
    <material name="Purple3">
        <color rgba="0.4 0.0 0.5 1.0"/>
    </material>
    <material name="Purple4">
        <color rgba="0.5 0.0 0.6 1.0"/>
    </material>
    <material name="Purple5">
        <color rgba="0.6 0.0 0.7 1.0"/>
    </material>
    <material name="Purple6">
        <color rgba="0.7 0.0 0.8 1.0"/>
    </material>
    <material name="Purple7">
        <color rgba="0.8 0.2 0.9 1.0"/>
    </material>
    <material name="Purple8">
        <color rgba="0.8 0.5 0.9 1.0"/>
    </material>

    <link name="base_link">
        <visual>
            <origin rpy="0 0 0" xyz="0 0 0"/>
            <geometry>
                <mesh filename="package://kawasaki_fs20n_description/meshes/base_link.stl"/>
            </geometry>
            <material name="Purple1" />
        </visual>
        <collision>
            <geometry>
                <mesh filename="package://kawasaki_fs20n_description/meshes/base_link.stl"/>
            </geometry>
        </collision>
    </link>

    <link name="link1">
        <visual>
            <origin rpy="0 0 0" xyz="0 0 0"/>
            <geometry>
                <mesh filename="package://kawasaki_fs20n_description/meshes/link_1.stl"/>
            </geometry>
            <material name="Purple2" />
        </visual>
        <collision>
            <geometry>
                <mesh filename="package://kawasaki_fs20n_description/meshes/link_1.stl"/>
            </geometry>
        </collision>
    </link>

    <link name="link2">
        <visual>
            <origin rpy="0 0 0" xyz="0 0 0"/>
            <geometry>
                <mesh filename="package://kawasaki_fs20n_description/meshes/link_2.stl"/>
            </geometry>
            <material name="Purple3" />
        </visual>
        <collision>
            <geometry>
                <mesh filename="package://kawasaki_fs20n_description/meshes/link_2.stl"/>
            </geometry>
        </collision>
    </link>

    <link name="link3">
        <visual>
            <origin rpy="0 0 0" xyz="0 0 0"/>
            <geometry>
                <mesh filename="package://kawasaki_fs20n_description/meshes/link_3.stl"/>
            </geometry>
            <material name="Purple4"/>
        </visual>
        <collision>
            <geometry>
                <mesh filename="package://kawasaki_fs20n_description/meshes/link_3.stl"/>
            </geometry>
        </collision>
    </link>

    <link name="link4">
        <visual>
            <origin rpy="0 0 0" xyz="0 0 0"/>
            <geometry>
                <mesh filename="package://kawasaki_fs20n_description/meshes/link_4.stl"/>
            </geometry>
            <material name="Purple5" />
        </visual>
        <collision>
            <geometry>
                <mesh filename="package://kawasaki_fs20n_description/meshes/link_4.stl"/>
            </geometry>
        </collision>
    </link>

    <link name="link5">
        <visual>
            <origin rpy="0 0 0" xyz="0 0 0"/>
            <geometry>
                <mesh filename="package://kawasaki_fs20n_description/meshes/link_5.stl"/>
            </geometry>
            <material name="Purple6" />
        </visual>
        <collision>
            <geometry>
                <mesh filename="package://kawasaki_fs20n_description/meshes/link_5.stl"/>
            </geometry>
        </collision>
    </link>

    <link name="link6">
        <visual>
            <origin rpy="0 0 0" xyz="0 0 0"/>
            <geometry>
                <mesh filename="package://kawasaki_fs20n_description/meshes/link_6.stl"/>
            </geometry>
            <material name="Purple7" />
        </visual>
        <collision>
            <geometry>
                <mesh filename="package://kawasaki_fs20n_description/meshes/link_6.stl"/>
            </geometry>
        </collision>
    </link>

    <joint name="joint0" type="revolute">
        <limit effort="1000.0" lower="-2.7925" upper="2.7925" velocity="0.5"/>
        <parent link="base_link"/>
        <child link="link1"/>
        <origin xyz="0 0 1.13" rpy="3.1415926 0 0" />
        <axis xyz="0 0 1" />
    </joint>

    <joint name="joint1" type="revolute">
        <limit effort="1000.0" lower="-1.8326" upper="2.4435" velocity="0.5"/>
        <parent link="link1"/>
        <child link="link2"/>
        <origin xyz="0.035 -0.150 -0.310" rpy="3.1415926 1.570796 0" />
        <axis xyz="0 0 1" />
    </joint>

    <joint name="joint2" type="revolute">
        <limit effort="1000.0" lower="-2.7053" upper="2.0944" velocity="0.5"/>
        <parent link="link2"/>
        <child link="link3"/>
        <origin xyz="0.8 0 0" rpy="3.1415926 0 0" />
        <axis xyz="0 0 1" />
    </joint>

    <joint name="joint3" type="revolute">
        <limit effort="1000.0" lower="-4.7124" upper="4.7124" velocity="0.5"/>
        <parent link="link3"/>
        <child link="link4"/>
        <origin xyz="0.225 0.06 -0.042" rpy="0 1.570796 0" />
        <axis xyz="0 0 1" />
    </joint>

    <joint name="joint4" type="revolute">
        <limit effort="1000.0" lower="-2.5307" upper="2.5307" velocity="0.5"/>
        <parent link="link4"/>
        <child link="link5"/>
        <origin xyz="0 0 0.475" rpy="0 -1.570796 0" />
        <axis xyz="0 0 1" />
    </joint>

    <joint name="joint5" type="revolute">
        <limit effort="1000.0" lower="-6.2832" upper="6.2832" velocity="0.5"/>
        <parent link="link5"/>
        <child link="link6"/>
        <origin xyz="0.0525 0 0" rpy="3.1415926 -1.570796 0" />
        <axis xyz="0 0 1" />
    </joint>
</robot>


